Workbook
Name Base: 'Caisse à Plateau'!$C$35
Name Base: 'Caisse Garde-Meubles'!#REF!
Name Base: 'Claire-Voie'!$C$30
Name Base: 'Objet 1'!$C$36
Name Base: 'Wrapp Barré'!$C$27
Name Base_OAV: ' Objet Anti Vibratoire'!$C$33
Name Base1: '1 Caisson Objet'!$C$25
Name Base1: '6 Caissons Objets'!$C$22
Name Base1: 'Objet 2 à 6'!$C$29
Name Base2: '1 Caisson Objet'!#REF!
Name Base2: '6 Caissons Objets'!$C$32
Name Base2: 'Objet 2 à 6'!$C$36
Name Base3: '1 Caisson Objet'!#REF!
Name Base3: '6 Caissons Objets'!$C$42
Name Base3: 'Objet 2 à 6'!$C$43
Name Base4: '1 Caisson Objet'!$H$25
Name Base4: '6 Caissons Objets'!$H$22
Name Base4: 'Objet 2 à 6'!$H$29
Name Base5: '1 Caisson Objet'!#REF!
Name Base5: '6 Caissons Objets'!$H$32
Name Base5: 'Objet 2 à 6'!$H$36
Name Base6: '1 Caisson Objet'!#REF!
Name Base6: '6 Caissons Objets'!$H$42
Name Base6: 'Objet 2 à 6'!$H$43
Name BaseP: 'Caisse à Plateau'!$C$32
Name BaseP: Palette!$C$21
Name Carton: '[1]Prix Matiere'!$J$11
Name Carton: '[1]Prix Matiere'!$J$11
Name Carton: '[1]Prix Matiere'!$J$11
Name Carton: '[1]Prix Matiere'!$J$11
Name Carton: '[1]Prix Matiere'!$J$11
Name Carton: '[1]Prix Matiere'!$J$11
Name Carton: '[1]Prix Matiere'!$J$11
Name Carton: '[1]Prix Matiere'!$J$11
Name Carton: '[1]Prix Matiere'!$J$11
Name Carton: '[1]Prix Matiere'!$J$11
Name Carton: '[1]Prix Matiere'!$J$11
Name Carton: '[1]Prix Matiere'!$J$11
Name Carton: 'Prix Matiere'!$J$11
Name CCBase1: 'Caisse Cuvette'!$C$28
Name CCBase2: 'Caisse Cuvette'!$C$35
Name CCBase3: 'Caisse Cuvette'!$C$42
Name CCBase4: 'Caisse Cuvette'!$I$28
Name CCBase5: 'Caisse Cuvette'!$I$35
Name CCBase6: 'Caisse Cuvette'!$I$42
Name CCType_de_mousse1: 'Caisse Cuvette'!$F$26
Name CCType_de_mousse2: 'Caisse Cuvette'!$F$33
Name CCType_de_mousse3: 'Caisse Cuvette'!$F$40
Name CCType_de_mousse4: 'Caisse Cuvette'!$L$26
Name CCType_de_mousse5: 'Caisse Cuvette'!$L$33
Name CCType_de_mousse6: 'Caisse Cuvette'!$L$40
Name Dimensions_intérieures_CP_15_hauteur: 'Caisse à Plateau'!$E$92
Name Dimensions_intérieures_CP_15_hauteur: 'Caisse Cuvette'!$E$95
Name Dimensions_intérieures_CP_15_hauteur: 'Caisse Garde-Meubles'!#REF!
Name Dimensions_intérieures_CP_15_hauteur: 'Claire-Voie'!$E$58
Name Dimensions_intérieures_CP_15_hauteur: 'Objet 1'!$E$93
Name Dimensions_intérieures_CP_15_hauteur: 'Objet 2 à 6'!$E$109
Name Dimensions_intérieures_CP_15_hauteur: Tapisserie!$E$90
Name Dimensions_intérieures_CP_15_hauteur: 'Wrapp Barré'!$E$54
Name Dimensions_intérieures_CP_15_hauteur_OAV: ' Objet Anti Vibratoire'!$E$98

Sheet T1
A1: Caisse Tableau
E3: =IF(C19="Boulons et platines","Boulons et platines",0) -> 0 | F3: =IF(E3="Boulons et Platines","Nbre de Trous",0) -> 0 | G3: =IF(E3="Boulons et Platines","Dim du Bord",0) -> 0
E4: =IF(C19="Vis bois",0,"Trous dans la Longueur") -> 0 | F4: =IF(E4=0,0,IF(C58<100,2,IF(C58<150,3,IF(C58<200,4,IF(C58<250,5,IF(C58<300,6,7)))))) -> 0 | G4: =IF(F4=0,0,IF(F4=3,0,(($C$58-32)/(F4-1))+16)) -> 0
E5: =IF(F4=6,"2ème Trou",IF(F4=7,"2ème Trou",0)) -> 0 | G5: =IF(E5=0,0,G4+G4-16) -> 0
E6: =IF(C19="Vis bois",0,"Trous dans la Hauteur") -> 0 | F6: =IF(E6=0,0,IF(D58<100,2,IF(D58<150,3,IF(D58<200,4,IF(D58<250,5,IF(D58<310,6,7)))))) -> 0 | G6: =IF(F6=0,0,IF(F6=3,0,(($D$58-32)/(F6-1))+16)) -> 0
E7: =IF(F6=6,"2ème Trou",IF(F6=7,"2ème Trou",0)) -> 0 | G7: =IF(E7=0,0,G6+G6-16) -> 0
B9: N° de dossier | C9: 1 | E9: Responsable Dossier | F9: Grégory MORA
B10: Ville de destination | C10: 1 | E10: Client | F10: ESI
B11: Caisse N° | C11: 1 | E11: Délai | F11: 1
B13: Type de Contreplaqué | C13: Peuplier 15 mm
B15: Barres | C15: Pin raboté 4 faces | E15: Garnissage Valsem | F15: Oui
B17: Type d'isolant | C17: Aucun
B19: Fermeture | C19: Vis bois | E19: Peinture | F19: Non
E20: =IF(F19="Oui","Type de Peinture",0) -> 0 | F20: =IF(F19="Non",0,VLOOKUP(F10,'Infos Clients'!B2:E10,4)) -> 0
B21: Poignées | C21: Bois | E21: Tyvek | F21: Non
B23: Skis | C23: Skis | E23: Option Calage | F23: Aucun
E25: Epaisseur Mousse | F25: PU 50 mm
B26: =IF(F23="Aucun"," ",F23) | D26: =IF(F21="Oui","+",0) -> 0 | E26: =IF(F21="Oui","Mousse Garnie Tyvek",0) -> 0
B28: =IF(B34="Aucun","Dimensions intérieures utiles","Dimensions de l'œuvre") -> Dimensions de l'œuvre | C28: Longueur | D28: Epaisseur | E28: Hauteur
C29: 100 | D29: 5 | E29: 100
B33: Type de calage
B34: Bandes de mousse
C35: Largeur | D35: Longueur | E35: Epaisseur | F35: Quantité
B36: Dessus | C36: 5
B37: Dessous | C37: 5
B38: Ethafoam 50 mm | C38: =+IF(C29=0,0,IF(C29>70,12,6)) -> 12 | F38: =IF(C29>300,6,IF(C29>250,5,IF(C29>200,4,IF(C29>150,3,IF(C29>120,3,2))))) -> 2 | G38: ,
B39: Rattrapage
B41: Remplissage 1
B42: Remplissage 2
B44: Dimensions intérieures caisse | C44: =C29+VLOOKUP(C17,B142:Q148,2)+VLOOKUP(B34,B169:M177,2) -> 110.2 | D44: =D29+VLOOKUP($B$34,B169:M177,3)+VLOOKUP($C$17,B142:Q148,3) -> 16 | E44: =E29+VLOOKUP($B$34,B169:M177,4)+VLOOKUP($C$17,B142:Q148,4) -> 110.2 | F44: Prix d'achat Arckx
B46: Dimensions extérieures caisse | C46: =C44+VLOOKUP(C21,B153:C156,2)+VLOOKUP(C13,B132:F134,5)*2+VLOOKUP(C15,B136:E137,4)*2 -> 121.6 | D46: =IF(OR($F$23="Aucun",$F$23="Stabilisateur"),$D$44+VLOOKUP($C$13,$B$132:$F$134,4)*2+VLOOKUP($C$15,$B$136:$E$137,4)*2+0.5,$E$44+VLOOKUP($C$13,$B$132:$F$134,5)*2+VLOOKUP($C$15,$B$136:$E$137,4)*2) -> 23.7 | E46: =IF(OR($F$23="Aucun",$F$23="Stabilisateur"),$E$44+VLOOKUP($C$13,$B$132:$F$134,5)*2+VLOOKUP($C$15,$B$136:$E$137,4)*2+VLOOKUP($C$23,$B$185:$C$187,2),$D$44+VLOOKUP($C$13,$B$132:$F$134,4)*2+VLOOKUP($C$15,$B$136:$E$137,4)*2+VLOOKUP($C$23,$B$185:$C$187,2)+VLOOKUP($F$23,$B$158:$E$161,4)+0.5) -> 120.4 | F46: =ROUNDUP(C129,0) -> 386
B48: Poids de la Caisse | C48: =Q121 -> 40.93123 | D48: Kg | E48: Bilan Carbone
B49: Minutes de Production | C49: =D123 -> 120.02949 | D49: Min | E49: =R121 -> 29.294938
B52: Commentaires
Q56: Poids en Kg | R56: CO²
F57: Quantité
B58: Grand côtés | C58: =IF(C44=0,0,C44+2*(VLOOKUP(E59,B132:E134,4)+VLOOKUP(C15,B136:E137,4))) -> 117.4 | D58: =IF(E44=0,0,E44+2*(VLOOKUP(E60,B132:E134,4)+VLOOKUP(C15,B136:E137,4))) -> 117.4 | E58: =VLOOKUP($C$13,$B$132:$E$134,2) -> Peuplier 15 mm | F58: 2 | J58: =IF(C58=0,0,(C58/100)*(D58/100)*F58) -> 2.756552 | K58: =J58/0.8 -> 3.44569 | L58: =IF(E58=0,0,VLOOKUP(E58,'Prix Matiere'!$A$4:$J$65,10)) -> 16.895876 | M58: =L58*K58-IF($F$15="Non",K58*0.75,0) -> 58.217952 | N58: =IF(J58=0,0,IF($F$15="Oui",(7.0924*J58)+15,(6.0924*J58)+10)) -> 34.550569 | O58: =N58*MinuteMO -> 29.367984 | Q58: =IF(J58=0,0,J58*VLOOKUP(E58,'Prix Matiere'!$A$4:$L$60,12)) -> 18.193243 | R58: =IF(J58=0,0,Q58*VLOOKUP(E58,'Prix Matiere'!$A$4:$L$60,11)) -> 14.063377
B59: Dessus dessous | C59: =C58 -> 117.4 | D59: =D44 -> 16 | E59: =VLOOKUP($C$13,$B$132:$E$134,3) -> Peuplier 15 mm | F59: 2 | J59: =IF(C59=0,0,(C59/100)*(D59/100)*F59) -> 0.37568 | K59: =J59/0.8 -> 0.4696 | L59: =IF(E59=0,0,VLOOKUP(E59,'Prix Matiere'!$A$4:$J$65,10)) -> 16.895876 | M59: =L59*K59-IF($F$15="Non",K59*0.75,0) -> 7.9343035 | N59: =IF(J59=0,0,IF($F$15="Oui",(7.0924*J59)+15,(6.0924*J59)+10)) -> 17.664473 | O59: =N59*MinuteMO -> 15.014802 | Q59: =IF(J59=0,0,J59*VLOOKUP(E59,'Prix Matiere'!$A$4:$L$60,12)) -> 2.479488 | R59: =IF(J59=0,0,Q59*VLOOKUP(E59,'Prix Matiere'!$A$4:$L$60,11)) -> 1.9166442
B60: Bouts | C60: =E44 -> 110.2 | D60: =D44 -> 16 | E60: =VLOOKUP($C$13,$B$132:$E$134,3) -> Peuplier 15 mm | F60: 2 | J60: =IF(C60=0,0,(C60/100)*(D60/100)*F60) -> 0.35264 | K60: =J60/0.8 -> 0.4408 | L60: =IF(E60=0,0,VLOOKUP(E60,'Prix Matiere'!$A$4:$J$65,10)) -> 16.895876 | M60: =L60*K60-IF($F$15="Non",K60*0.75,0) -> 7.4477023 | N60: =IF(J60=0,0,IF($F$15="Oui",(7.0924*J60)+15,(6.0924*J60)+10)) -> 17.501064 | O60: =N60*MinuteMO -> 14.875904 | Q60: =IF(J60=0,0,J60*VLOOKUP(E60,'Prix Matiere'!$A$4:$L$60,12)) -> 2.327424 | R60: =IF(J60=0,0,Q60*VLOOKUP(E60,'Prix Matiere'!$A$4:$L$60,11)) -> 1.7990988
J61: =IF(C61=0,0,(C61/100)*(D61/100)*F61) -> 0 | K61: =J61/0.8 -> 0
...

Sheet T1-T6
A1: Caisse Tableau de 1 à 6 Œuvres
E3: =IF(C19="Boulons et platines","Boulons et Platines",0) -> 0 | F3: =IF(E3="Boulons et Platines","Nbre de Trous",0) -> 0 | G3: =IF(E3="Boulons et Platines","Dim du Bord",0) -> 0
E4: =IF(C19="Vis bois",0,"Trous dans la Longueur") -> 0 | F4: =IF(E4=0,0,IF(C90<100,2,IF(C90<150,3,IF(C90<200,4,IF(C90<250,5,IF(C90<300,6,7)))))) -> 0 | G4: =IF(F4=0,0,IF(F4=3,0,(($C$90-32)/(F4-1))+16)) -> 0
E5: =IF(F4=6,"2ème Trou",IF(F4=7,"2ème Trou",0)) -> 0 | G5: =IF(E5=0,0,G4+G4-16) -> 0
E6: =IF(C19="Vis bois",0,"Trous dans la Hauteur") -> 0 | F6: =IF(E6=0,0,IF(D90<100,2,IF(D90<150,3,IF(D90<200,4,IF(D90<250,5,IF(D90<310,6,7)))))) -> 0 | G6: =IF(F6=0,0,IF(F6=3,0,(($D$90-32)/(F6-1))+16)) -> 0
E7: =IF(F6=6,"2ème Trou",IF(F6=7,"2ème Trou",0)) -> 0 | G7: =IF(E7=0,0,G6+G6-16) -> 0
B9: N° de dossier | E9: Responsable Dossier | F9: Grégory MORA
B10: Ville de destination | E10: Client | F10: ESI
B11: N° de caisse | E11: Délai
B13: Type de Contreplaqué | C13: Peuplier 15 mm | H13: =VLOOKUP($F$10,'Infos Clients'!$B$2:$G$10,2) -> #VALUE!
B15: Barres | C15: Pin raboté 4 faces | E15: Garnissage Valsem | F15: Oui
B17: Type d'isolant | C17: Super isotherme en 30
B19: Fermeture | C19: Vis bois | E19: Peinture | F19: Non
E20: =IF(F19="Oui","Type de Peinture",0) -> 0 | F20: =IF(F19="Non",0,VLOOKUP(F10,'Infos Clients'!B2:E10,4)) -> 0
B21: Poignées | C21: Bois | E21: Tyvek | F21: Non
B23: Skis | C23: Skis | E23: Option Calage | F23: Aucun
B24: =IF(F23="Aucun"," ",F23) | D24: =IF(F21="Oui","+",0) -> 0 | E24: =IF(F21="Oui","Mousse Garnie Tyvek",0) -> 0
B26: =IF(F10="Bovis","Attention retirer 2 mm aux dimensions transmises",0) -> 0
A28: =IF(B29="Aucun","Dimensions intérieures utiles","Dimensions de l'œuvre") -> Dimensions de l'œuvre | B28: Longueur | C28: Epaisseur | D28: Hauteur | E28: Mousse de Calage 1 | G28: =IF(H29="Aucun","Dimensions intérieures utiles","Dimensions de l'œuvre") -> Dimensions de l'œuvre | H28: Longueur | I28: Epaisseur | J28: Hauteur | K28: Mousse de Calage 2
B29: 62 | C29: 13 | D29: 43
A30: Type de calage | B30: Bandes de mousse | C30: N° d'inventaire | G30: Type de calage | H30: Aucun | I30: N° d'inventaire
B31: Largeur | C31: Longueur | D31: Epaisseur | E31: Quantité | H31: Largeur | I31: Longueur | J31: Epaisseur | K31: Quantité
A32: Dessus | B32: 10 | G32: Dessus
A33: Dessous | B33: 10 | G33: Dessous
A34: Agglocelle 50 mm | B34: =+IF(B29=0,0,IF(B29>70,12,6)) -> 6 | E34: =IF(B29>300,6,IF(B29>250,5,IF(B29>200,4,IF(B29>150,3,IF(B29>120,3,2))))) -> 2 | G34: Aucun | H34: =+IF(H29=0,0,IF(H29>70,12,6)) -> 0 | K34: =IF(H29>300,6,IF(H29>250,5,IF(H29>200,4,IF(H29>150,3,IF(H29>120,3,2))))) -> 2
A35: Rattrapage | G35: Rattrapage
A36: Remplissage 1 | G36: Remplissage 1
A37: Remplissage 2 | G37: Remplissage 2
A38: Dimensions nécéssaires | B38: =IF(B29=0,0,B29+VLOOKUP(B30,$A$282:$L$288,2)) -> 72.2 | C38: =IF(C29=0,0,C29+VLOOKUP(B30,$A$282:$L$288,3)) -> 24 | D38: =IF(D29=0,0,D29+VLOOKUP(B30,$A$282:$L$288,4)) -> 53.2 | G38: Dims nécéssaires | H38: =IF(H29=0,0,H29+VLOOKUP(H30,$A$282:$L$288,2)) -> 0 | I38: =IF(I29=0,0,I29+VLOOKUP(H30,$A$282:$L$288,3)) -> 0 | J38: =IF(J29=0,0,J29+VLOOKUP(H30,$A$282:$L$288,4)) -> 0
G40: Dims fond de caisse | H40: =IF(B41=0,0,MAX(B41,B56+5.5,B72+5.5)) -> 75.2 | I40: =C41 -> 24 | J40: =IF(D41=0,0,MAX(D41,D56+5.5,D72+5.5)) -> 56.2
A41: Dims necessaire fond de caisse | B41: =B38+IF(H38=0,0,1.5+H38) -> 72.2 | C41: =MAX(C38,I38) -> 24 | D41: =MAX(D38,J38) -> 53.2 | G41: Dims ext fond de caisse | H41: =IF(H40=0,0,H40) -> 75.2 | I41: =IF(I40=0,0,I40) -> 24 | J41: =IF(J40=0,0,J40) -> 56.2
A43: =IF(B44="Aucun","Dimensions intérieures utiles","Dimensions de l'œuvre") -> Dimensions de l'œuvre | B43: Longueur | C43: Epaisseur | D43: Hauteur | E43: Mousse de Calage 3 | G43: =IF(H44="Aucun","Dimensions intérieures utiles","Dimensions de l'œuvre") -> Dimensions de l'œuvre | H43: Longueur | I43: Epaisseur | J43: Hauteur | K43: Mousse de Calage 4
B44: 59 | C44: 8.5 | D44: 40.5
A45: Type de calage | B45: Bandes de mousse | C45: N° d'inventaire | G45: Type de calage | H45: Aucun | I45: N° d'inventaire
B46: Largeur | C46: Longueur | D46: Epaisseur | E46: Quantité | H46: Largeur | I46: Longueur | J46: Epaisseur | K46: Quantité
A47: Dessus | B47: 10 | G47: Dessus
A48: Dessous | B48: 10 | G48: Dessous
A49: Agglocelle 50 mm | B49: =+IF(B44=0,0,IF(B44>70,12,6)) -> 6 | E49: =IF(B44>300,6,IF(B44>250,5,IF(B44>200,4,IF(B44>150,3,IF(B44>120,3,2))))) -> 2 | G49: Aucun | H49: =+IF(H44=0,0,IF(H44>70,12,6)) -> 0 | K49: =IF(H44>300,6,IF(H44>250,5,IF(H44>200,4,IF(H44>150,3,IF(H44>120,3,2))))) -> 2
A50: Rattrapage | G50: Rattrapage
A51: Remplissage 1 | G51: Remplissage 1
...

Sheet T1-T6 + Caissons
A1: Caisse Objet et Caissons Tableaux de 2 à 6 Œuvres
E3: =IF(C19="Boulons et platines","Boulons et Platines GC",0) -> 0 | F3: =IF(E3="Boulons et Platines GC","Nbre de Trous",0) -> 0 | G3: =IF(E3="Boulons et Platines GC","Dim du Bord",0) -> 0 | H3: =IF(C19="Boulons et platines","Boulons et Platines CV",0) -> 0 | I3: =IF(H3="Boulons et Platines CV","Nbre de Trous",0) -> 0 | J3: =IF(H3="Boulons et Platines CV","Dim du Bord",0) -> 0
E4: =IF(C19="Vis bois",0,"Trous dans la Longueur") -> 0 | F4: =IF(E4=0,0,IF(C91<100,2,IF(C91<150,3,IF(C91<200,4,IF(C91<250,5,IF(C91<300,6,7)))))) -> 0 | G4: =IF(F4=0,0,IF(F4=2,0,IF(F4=3,0,(($C$91-32)/(F4-1))+16))) -> 0 | H4: =IF(C19="Vis bois",0,"Trous dans la Longueur") -> 0 | I4: =IF(H4=0,0,IF(C92<100,2,IF(C92<150,3,IF(C92<200,4,IF(C92<250,5,IF(E51<300,6,7)))))) -> 0 | J4: =IF(I4=0,0,IF(I4=2,0,IF(I4=3,0,(($C$92-32)/(I4-1))+16))) -> 0
E5: =IF(F4=6,"2ème Trou",IF(F4=7,"2ème Trou",0)) -> 0 | G5: =IF(E5=0,0,G4+G4-16) -> 0 | H5: =IF(I4=6,"2ème Trou",IF(I4=7,"2ème Trou",0)) -> 0 | J5: =IF(H5=0,0,J4+J4-16) -> 0
E6: =IF(C19="Vis bois",0,"Trous dans la Hauteur") -> 0 | F6: =IF(E6=0,0,IF(D91<100,2,IF(D91<150,3,IF(D91<200,4,IF(D91<250,5,IF(D91<310,6,7)))))) -> 0 | G6: =IF(F6=0,0,IF(F6=2,0,IF(F6=3,0,(($D$91-32)/(F6-1))+16))) -> 0 | H6: =IF(C19="Vis bois",0,"Trous dans la Largeur") -> 0 | I6: =IF(H6=0,0,IF(D92<50,1,IF(D92<100,2,IF(D92<150,3,IF(D92<200,4,IF(D92<250,5,IF(D92<310,6,7))))))) -> 0 | J6: =IF(I6=0,0,IF(I6=1,0,IF(I6=2,0,IF(I6=3,0,(($D$92-32)/(I6-1))+16)))) -> 0
E7: =IF(F6=6,"2ème Trou",IF(F6=7,"2ème Trou",0)) -> 0 | G7: =IF(E7=0,0,G6+G6-16) -> 0 | H7: =IF(I6=6,"2ème Trou",IF(I6=7,"2ème Trou",0)) -> 0 | J7: =IF(H7=0,0,J6+J6-16) -> 0
B9: N° de dossier | E9: Responsable Dossier | F9: Grégory MORA
B10: Ville de destination | E10: Client | F10: ESI
B11: N° de caisse | E11: Délai
B13: Type de Contreplaqué | C13: Peuplier 15 mm
H14: =VLOOKUP($F$10,'Infos Clients'!$B$2:$G$10,2) -> #VALUE!
B15: Barres | C15: Pin raboté 4 faces | E15: Garnissage Valsem | F15: Oui
B17: Type d'isolant | C17: Aucun
B19: Fermeture | C19: Vis bois | E19: Peinture | F19: Non
E20: =IF(F19="Oui","Type de Peinture",0) -> 0 | F20: =IF(F19="Non",0,VLOOKUP(F10,'Infos Clients'!B2:E10,4)) -> 0
B21: Poignées | C21: Bois | E21: Tyvek | F21: Non
B23: Skis | C23: 10 dessous en skis | E23: Option Calage | F23: Aucun
B24: =IF(F23="Aucun"," ",F23) | D24: =IF(F21="Oui","+",0) -> 0 | E24: =IF(F21="Oui","Mousse Garnie Tyvek",0) -> 0
B25: =IF(F10="Bovis","Attention retirer 2 mm aux dimensions transmises",0) -> 0
A27: =IF(B28="Aucun","Dimensions intérieures utiles","Dimensions de l'œuvre") -> Dimensions de l'œuvre | B27: Longueur | C27: Epaisseur | D27: Hauteur | E27: Mousse de Calage 1 | G27: =IF(H28="Aucun","Dimensions intérieures utiles","Dimensions de l'œuvre") -> Dimensions de l'œuvre | H27: Longueur | I27: Epaisseur | J27: Hauteur | K27: Mousse de Calage 2
A29: Type de calage | B29: Aucun | C29: N° d'inventaire | G29: Type de calage | H29: Aucun | I29: N° d'inventaire
B30: Largeur | C30: Longueur | D30: Epaisseur | E30: Quantité | H30: Largeur | I30: Longueur | J30: Epaisseur | K30: Quantité
A31: Dessus | G31: Dessus
A32: Dessous | G32: Dessous
A33: Ethafoam 50 mm | B33: =+IF(B28=0,0,IF(B28>70,12,6)) -> 0 | E33: =IF(B28>300,6,IF(B28>250,5,IF(B28>200,4,IF(B28>150,3,IF(B28>120,3,2))))) -> 2 | G33: Ethafoam 50 mm | H33: =+IF(H28=0,0,IF(H28>70,12,6)) -> 0 | K33: =IF(H28>300,6,IF(H28>250,5,IF(H28>200,4,IF(H28>150,3,IF(H28>120,3,2))))) -> 2
A34: Rattrapage | G34: Rattrapage
A35: Remplissage 1 | G35: Remplissage 1
A36: Remplissage 2 | G36: Remplissage 2
A37: Dims nécéssaires | B37: =IF(B28=0,0,B28+VLOOKUP(B29,$A$292:$L$297,2)) -> 0 | C37: =IF(C28=0,0,C28+VLOOKUP(B29,$A$292:$L$297,3)) -> 0 | D37: =IF(D28=0,0,D28+VLOOKUP(B29,$A$292:$L$297,4)) -> 0 | G37: Dims nécéssaires | H37: =IF(H28=0,0,H28+VLOOKUP(H29,$A$292:$L$297,2)) -> 0 | I37: =IF(I28=0,0,I28+VLOOKUP(H29,$A$292:$L$297,3)) -> 0 | J37: =IF(J28=0,0,J28+VLOOKUP(H29,$A$292:$L$297,4)) -> 0
G39: Dims int Caisson | H39: =IF(H41=0,0,H40-3) -> 0 | I39: =IF(I41=0,0,I40-3.5) -> 0 | J39: =IF(J41=0,0,J40-3) -> 0
A40: Dims necessaire Caissons 1 | B40: =B37+IF(H37=0,0,1.5+H37) -> 0 | C40: =MAX(C37,I37) -> 0 | D40: =MAX(D37,J37) -> 0 | G40: Dims ext Caisson | H40: =IF(H41=0,0,H41) -> 0 | I40: =IF(I41=0,0,I41) -> 0 | J40: =IF(J41=0,0,J41) -> 0
G41: Dims nec caisse | H41: =IF(B40=0,0,MAX(B40+3,B56+3,B72+3)) -> 0 | I41: =IF(C40=0,0,C40+3.5) -> 0 | J41: =IF(D40=0,0,MAX(D40+3,D56+3,D72+3)) -> 0
A43: =IF(B44="Aucun","Dimensions intérieures utiles","Dimensions de l'œuvre") -> Dimensions de l'œuvre | B43: Longueur | C43: Epaisseur | D43: Hauteur | E43: Mousse de Calage 3 | G43: =IF(H44="Aucun","Dimensions intérieures utiles","Dimensions de l'œuvre") -> Dimensions de l'œuvre | H43: Longueur | I43: Epaisseur | J43: Hauteur | K43: Mousse de Calage 4
A45: Type de calage | B45: Aucun | C45: N° d'inventaire | G45: Type de calage | H45: Aucun | I45: N° d'inventaire
B46: Largeur | C46: Longueur | D46: Epaisseur | E46: Quantité | H46: Largeur | I46: Longueur | J46: Epaisseur | K46: Quantité
A47: Dessus | G47: Dessus
A48: Dessous | G48: Dessous
A49: Ethafoam 50 mm | B49: =+IF(B44=0,0,IF(B44>70,12,6)) -> 0 | E49: =IF(B44>300,6,IF(B44>250,5,IF(B44>200,4,IF(B44>150,3,IF(B44>120,3,2))))) -> 2 | G49: Ethafoam 50 mm | H49: =+IF(H44=0,0,IF(H44>70,12,6)) -> 0 | K49: =IF(H44>300,6,IF(H44>250,5,IF(H44>200,4,IF(H44>150,3,IF(H44>120,3,2))))) -> 2
A50: Rattrapage | G50: Rattrapage
A51: Remplissage 1 | G51: Remplissage 1
...

Sheet T1-T3 MRT
A1: Caisse Tableau de 1 à 3 MRT
E3: =IF(C19="Boulons et platines","Boulons et Platines",0) -> 0 | F3: =IF(E3="Boulons et Platines","Nbre de Trous",0) -> 0 | G3: =IF(E3="Boulons et Platines","Dim du Bord",0) -> 0
E4: =IF(C19="Vis bois",0,"Trous dans la Longueur") -> 0 | F4: =IF(E4=0,0,IF(C52<100,2,IF(C52<150,3,IF(C52<200,4,IF(C52<250,5,IF(C52<300,6,7)))))) -> 0 | G4: =IF(F4=0,0,IF(F4=3,0,(($C$52-32)/(F4-1))+16)) -> 0
E5: =IF(F4=6,"2ème Trou",IF(F4=7,"2ème Trou",0)) -> 0 | G5: =IF(E5=0,0,G4+G4-16) -> 0
E6: =IF(C19="Vis bois",0,"Trous dans la Hauteur") -> 0 | F6: =IF(E6=0,0,IF(D52<100,2,IF(D52<150,3,IF(D52<200,4,IF(D52<250,5,IF(D52<310,6,7)))))) -> 0 | G6: =IF(F6=0,0,IF(F6=3,0,(($D$52-32)/(F6-1))+16)) -> 0
E7: =IF(F6=6,"2ème Trou",IF(F6=7,"2ème Trou",0)) -> 0 | G7: =IF(E7=0,0,G6+G6-16) -> 0
B9: N° de dossier | E9: Responsable Dossier | F9: Grégory MORA
B10: Ville de destination | E10: Client | F10: ESI
B11: N° de caisse | E11: Délai
B13: Type de Contreplaqué | C13: Peuplier 15 mm
B15: Barres | C15: Pin raboté 4 faces | E15: Garnissage Valsem | F15: Oui | H15: =VLOOKUP($F$10,'Infos Clients'!$B$2:$G$10,2) -> #VALUE!
B17: Type d'isolant | C17: Isotherme en 30
B19: Fermeture | C19: Vis bois | E19: Peinture | F19: Non
E20: =IF(F19="Oui","Type de Peinture",0) -> 0 | F20: =IF(F19="Non",0,VLOOKUP(F10,'Infos Clients'!B2:E10,4)) -> 0
B21: Poignées | C21: Bois
B23: Skis | C23: Skis | E23: Option Calage | F23: Aucun
B24: =IF(F23="Aucun"," ",F23)
C26: Longueur | D26: Epaisseur | E26: Hauteur | F26: =IF(B27="Dimensions de l'œuvre","Face du MRT",0) -> Face du MRT | G26: =IF(B27="Dimensions de l'œuvre","Arrière du MRT",0) -> Arrière du MRT | H26: Prix du MRT
B27: Dimensions de l'oeuvre | C27: 207.2 | D27: 4.2 | E27: 166.5 | F27: Mrt Ouvert | G27: Mrt Ouvert | H27: =S72 -> 190.90207 | J27: =IF($B$27="Dimensions ext MRT existant",C27,IF($B$27="Aucun",0,C27+24.2)) -> 231.4 | K27: =IF($B$27="Dimensions ext MRT existant",K28,IF($B$27="Aucun",0,K28+1.5+VLOOKUP($G$27,$A$170:$C$174,3)+VLOOKUP($F$27,A170:C174,3))) -> 13.9 | L27: =IF($B$27="Dimensions ext MRT existant",E27,IF($B$27="Aucun",0,E27+14.2)) -> 180.7
K28: =IF(B27="Dimensions ext MRT existant",D27,IF(B27="Aucun",0,IF(D27<6,9.4,IF(D27<11,14.4,D27+9.4)))) -> 9.4
C29: Longueur | D29: Epaisseur | E29: Hauteur | F29: =IF(B30="Dimensions de l'œuvre","Type de MRT",0) -> 0 | G29: Prix du MRT | H29: Prix du MRT
B30: Aucun | F30: Mrt Ouvert | G30: Mrt Ouvert | H30: =S80 -> 0 | J30: =IF($B$30="Dimensions ext MRT existant",C30,IF($B$30="Aucun",0,C30+24.2)) -> 0 | K30: =IF($B$30="Dimensions ext MRT existant",D30,IF($B$30="Aucun",0,K31+1.5+VLOOKUP($G$30,$A$170:$C$174,3)+VLOOKUP($F$30,$A$170:$C$174,3))) -> 0 | L30: =IF($B$30="Dimensions ext MRT existant",E30,IF($B$30="Aucun",0,E30+14.2)) -> 0
K31: =IF(B30="Dimensions ext MRT existant",D30,IF(B30="Aucun",0,IF(D30<6,9.4,IF(D30<11,14.4,D30+9.4)))) -> 0
C32: Longueur | D32: Epaisseur | E32: Hauteur | F32: =IF(B33="Dimensions de l'œuvre","Type de MRT",0) -> 0 | G32: Prix du MRT | H32: Prix du MRT
B33: Aucun | F33: Mrt Ouvert | G33: Mrt Ouvert | H33: =S88 -> 0 | J33: =IF($B$33="Dimensions ext MRT existant",C33,IF($B$33="Aucun",0,C33+24.2)) -> 0 | K33: =IF($B$33="Dimensions ext MRT existant",D33,IF($B$33="Aucun",0,K34+1.5+VLOOKUP($G$33,$A$170:$C$174,3)+VLOOKUP($F$33,$A$170:$C$174,3))) -> 0 | L33: =IF($B$33="Dimensions ext MRT existant",E33,IF($B$33="Aucun",0,E33+14.2)) -> 0
K34: =IF(B33="Dimensions ext MRT existant",D33,IF(B33="Aucun",0,IF(D33<6,9.4,IF(D33<11,14.4,D33+9.4)))) -> 0
B36: Type de calage
B37: Aucun
B39: Dimensions intérieures caisse | C39: =IF(J27=0,0,MAX(J27:J33)+VLOOKUP(C17,A146:P152,2)+VLOOKUP(B37,A178:D180,2)) -> 239.9 | D39: =K27+K30+K33+VLOOKUP($B$37,A178:D180,3)+VLOOKUP($C$17,A146:P152,3) -> 19.9 | E39: =IF(L27=0,0,MAX(L27:L33)+VLOOKUP($B$37,A178:D180,4)+VLOOKUP($C$17,A146:P152,4)) -> 189.2 | F39: Prix d'achat Arckx (y compris MRT à réaliser)
B41: Dimensions extérieures caisse | C41: =C39+VLOOKUP(C21,A157:B159,2)+VLOOKUP(C13,A136:E138,5)*2+VLOOKUP(C15,A140:D141,4)*2 -> 251.3 | D41: =IF(OR($F$23="Aucun",$F$23="Stabilisateur"),$D$39+VLOOKUP($C$13,$A$136:$E$138,4)*2+VLOOKUP($C$15,$A$140:$D$141,4)*2+0.5,$E$39+VLOOKUP($C$13,$A$136:$E$138,5)*2+VLOOKUP($C$15,$A$140:$D$141,4)*2) -> 27.6 | E41: =IF(OR($F$23="Aucun",$F$23="Stabilisateur"),$E$39+VLOOKUP($C$13,$A$136:$E$138,5)*2+VLOOKUP($C$15,$A$140:$D$141,4)*2+VLOOKUP($C$23,$A$186:$B$188,2),$D$39+VLOOKUP($C$13,$A$136:$E$138,4)*2+VLOOKUP($C$15,$A$140:$D$141,4)*2+VLOOKUP($C$23,$A$186:$B$188,2)+VLOOKUP($F$23,$A$161:$D$164,4)+0.5) -> 199.4 | F41: =ROUNDUP(C133,0) -> 1209
B43: Poids de la Caisse | C43: =P125 -> 141.64269 | D43: Kg | E43: Bilan Carbone
B44: Minutes de Production | C44: =D127 -> 284.60457 | D44: Min | E44: =Q125 -> 121.06331
B46: Commentaires
F51: Quantité | P51: Poids KG | Q51: CO²
A52: Grand côtés | B52: =VLOOKUP(C13,A136:D138,2) -> Peuplier 15 mm | C52: =IF(C39=0,0,C39+2*(VLOOKUP(B53,A136:D138,4)+VLOOKUP(C15,A140:D141,4))) -> 247.1 | D52: =IF(E39=0,0,E39+2*(VLOOKUP(B54,A136:D138,4)+VLOOKUP(C15,A140:D141,4))) -> 196.4 | E52: =B52 -> Peuplier 15 mm | F52: 2 | J52: =IF(C52=0,0,(C52/100)*(D52/100)*F52) -> 9.706088 | K52: =J52/0.8 -> 12.13261 | L52: =IF(E52=0,0,VLOOKUP(E52,'Prix Matiere'!$A$4:$J$65,10)) -> 16.895876 | M52: =L52*K52-IF($F$15="Non",K52*0.75,0) -> 204.99108 | N52: =IF(J52=0,0,IF($F$15="Oui",(7.0924*J52)+15,(6.0924*J52)+10)) -> 83.839459 | O52: =N52*MinuteMO -> 71.26354 | P52: =IF(J52=0,0,J52*VLOOKUP(E52,'Prix Matiere'!$A$4:$L$60,12)) -> 64.060181 | Q52: =IF(J52=0,0,P52*VLOOKUP(E52,'Prix Matiere'!$A$4:$L$60,11)) -> 49.51852
A53: Dessus dessous | B53: =VLOOKUP(C13,A136:D138,3) -> Peuplier 15 mm | C53: =C52 -> 247.1 | D53: =D39 -> 19.9 | E53: =B53 -> Peuplier 15 mm | F53: 2 | J53: =IF(C53=0,0,(C53/100)*(D53/100)*F53) -> 0.983458 | K53: =J53/0.8 -> 1.2293225 | L53: =IF(E53=0,0,VLOOKUP(E53,'Prix Matiere'!$A$4:$J$65,10)) -> 16.895876 | M53: =L53*K53-IF($F$15="Non",K53*0.75,0) -> 20.770481 | N53: =IF(J53=0,0,IF($F$15="Oui",(7.0924*J53)+15,(6.0924*J53)+10)) -> 21.975078 | O53: =N53*MinuteMO -> 18.678816 | P53: =IF(J53=0,0,J53*VLOOKUP(E53,'Prix Matiere'!$A$4:$L$60,12)) -> 6.4908228 | Q53: =IF(J53=0,0,P53*VLOOKUP(E53,'Prix Matiere'!$A$4:$L$60,11)) -> 5.017406
A54: Bouts | B54: =VLOOKUP(C13,A136:D138,3) -> Peuplier 15 mm | C54: =E39 -> 189.2 | D54: =D39 -> 19.9 | E54: =B54 -> Peuplier 15 mm | F54: 2 | J54: =IF(C54=0,0,(C54/100)*(D54/100)*F54) -> 0.753016 | K54: =J54/0.8 -> 0.94127 | L54: =IF(E54=0,0,VLOOKUP(E54,'Prix Matiere'!$A$4:$J$65,10)) -> 16.895876 | M54: =L54*K54-IF($F$15="Non",K54*0.75,0) -> 15.903581 | N54: =IF(J54=0,0,IF($F$15="Oui",(7.0924*J54)+15,(6.0924*J54)+10)) -> 20.340691 | O54: =N54*MinuteMO -> 17.289587 | P54: =IF(J54=0,0,J54*VLOOKUP(E54,'Prix Matiere'!$A$4:$L$60,12)) -> 4.9699056 | Q54: =IF(J54=0,0,P54*VLOOKUP(E54,'Prix Matiere'!$A$4:$L$60,11)) -> 3.841737
J55: =IF(C55=0,0,(C55/100)*(D55/100)*F55) -> 0 | K55: =J55/0.8 -> 0 | P55: =IF(J55=0,0,J55*VLOOKUP(E55,'Prix Matiere'!$A$4:$L$60,12)) -> 0 | Q55: =IF(J55=0,0,P55*VLOOKUP(E55,'Prix Matiere'!$A$4:$L$60,11)) -> 0
J56: =IF(C56=0,0,(C56/100)*(D56/100)*F56) -> 0 | K56: =J56/0.8 -> 0 | P56: =IF(J56=0,0,J56*VLOOKUP(E56,'Prix Matiere'!$A$4:$L$60,12)) -> 0 | Q56: =IF(J56=0,0,P56*VLOOKUP(E56,'Prix Matiere'!$A$4:$L$60,11)) -> 0
A57: Barres | B57: Barres de GC | C57: =C52 -> 247.1 | D57: =IF(D52>80,9.4,7) -> 9.4 | E57: =IF($C$15="Pin raboté 4 faces","Barres 21 R4F","Barres 19 mm") -> Barres 21 R4F | F57: 4 | J57: =IF(C57=0,0,(C57/100)*(D57/100)*F57) -> 0.929096 | K57: =J57/0.8 -> 1.16137 | L57: =IF(E57=0,0,VLOOKUP(E57,'Prix Matiere'!$A$4:$J$65,10)) -> 18.969072 | M57: =L57*K57 -> 22.030111 | N57: =IF(J57=0,0,1+(11*J57)) -> 11.220056 | O57: =N57*MinuteMO -> 9.5370476 | P57: =IF(J57=0,0,J57*VLOOKUP(E57,'Prix Matiere'!$A$4:$L$60,12)) -> 9.29096 | Q57: =IF(J57=0,0,P57*VLOOKUP(E57,'Prix Matiere'!$A$4:$L$60,11)) -> 4.4968246
...

Sheet MRT
A1: MRT
B4: N° de dossier | E4: Responsable Dossier | F4: Grégory MORA
B5: Ville de destination | E5: Client | F5: ESI
B6: N° de caisse | E6: Délai
B8: Type de Contreplaqué | C8: Peuplier 15 mm | E8: Catégorie | F8: MRT
E9: Clouage
B10: Barres | C10: Pin raboté 4 faces
B12: Fermeture | C12: Vis bois | E12: =VLOOKUP($F$5,'Infos Clients'!$B$2:$G$10,2) -> #VALUE!
B14: Poignées | C14: Métal x 2 sur bouts
C18: Longueur | D18: Epaisseur | E18: Hauteur | F18: =IF(B19="Dimensions de l'œuvre","Face du MRT",0) -> Face du MRT | G18: =IF(B19="Dimensions de l'œuvre","Arrière du MRT",0) -> Arrière du MRT
B19: Dimensions de l'oeuvre | C19: 244 | D19: 3.5 | E19: 246 | F19: Mrt Ouvert | G19: Mrt Ouvert
B23: Dimensions intérieures caisse | C23: =C25-4.2 -> 264 | D23: =IF(D19<6,9.4,IF(D19<11,14.4,D19+9.4)) -> 9.4 | E23: =E25-4.2 -> 256 | F23: Prix d'achat Arckx
B25: Dimensions extérieures caisse | C25: =IF($B$19="Dimensions ext MRT existant",C19,IF($B$19="Aucun",0,C19+24.2)) -> 268.2 | D25: =IF($B$19="Dimensions ext MRT existant",D19,IF($B$19="Aucun",0,D23+1.5+VLOOKUP($G$19,$A$77:$C$81,3)+VLOOKUP($F$19,A77:C81,3))) -> 13.9 | E25: =IF($B$19="Dimensions ext MRT existant",E19,IF($B$19="Aucun",0,E19+14.2)) -> 260.2 | F25: =C55 -> 246.63234
B27: Poids de la Caisse | C27: =P47 -> 30.98816 | D27: Kg | E27: Bilan Carbone
B28: Minutes de Production | C28: =D49 -> 68.348321 | D28: Min | E28: =Q47 -> 21.105764
B30: Commentaires
A34: MRT 1
P35: Poids KG | Q35: CO²
B36: Dessus dessous bois massif | C36: =IF(B19="Dimensions ext MRT existant",0,C25) -> 268.2 | D36: =IF(B19="Dimensions ext MRT existant",0,D23) -> 9.4 | E36: Barres 21 R4F | F36: =IF(C36=0,0,2) -> 2 | J36: =IF(C36=0,0,(C36/100)*(D36/100)*F36) -> 0.504216 | K36: =J36/0.8 -> 0.63027 | L36: =IF(E36=0,0,VLOOKUP(E36,'Prix Matiere'!$A$4:$J$65,10)) -> 18.969072 | M36: =L36*K36 -> 11.955637 | N36: =IF(C36=0,0,4+(11*J36)) -> 9.546376 | O36: =N36*MinuteMO -> 8.1144196 | P36: =IF(J36=0,0,J36*VLOOKUP(E36,'Prix Matiere'!$A$4:$L$60,12)) -> 5.04216 | Q36: =IF(J36=0,0,P36*VLOOKUP(E36,'Prix Matiere'!$A$4:$L$60,11)) -> 2.4404054
B37: Bouts bois massif avec poignées métalliques | C37: =IF(B19="Dimensions ext MRT existant",0,IF(E25=0,0,E25-4.2)) -> 256 | D37: =D36 -> 9.4 | E37: Barres 21 R4F | F37: =F36 -> 2 | J37: =IF(C37=0,0,(C37/100)*(D37/100)*F37) -> 0.48128 | K37: =J37/0.8 -> 0.6016 | L37: =IF(E37=0,0,VLOOKUP(E37,'Prix Matiere'!$A$4:$J$65,10)) -> 18.969072 | M37: =L37*K37 -> 11.411794 | N37: =IF(C37=0,0,4+(11*J37)) -> 9.29408 | O37: =N37*MinuteMO -> 7.899968 | P37: =IF(J37=0,0,J37*VLOOKUP(E37,'Prix Matiere'!$A$4:$L$60,12)) -> 4.8128 | Q37: =IF(J37=0,0,P37*VLOOKUP(E37,'Prix Matiere'!$A$4:$L$60,11)) -> 2.3293952
B38: =E38 -> Peuplier 15 mm | C38: =IF(C36=0,0,C36) -> 268.2 | D38: =IF(C38=0,0,25) -> 25 | E38: ="Peuplier 15 mm" -> Peuplier 15 mm | F38: =IF(C38=0,0,2) -> 2 | J38: =IF(C38=0,0,(C38/100)*(D38/100)*F38) -> 1.341 | K38: =J38/0.8 -> 1.67625 | L38: =IF(E38=0,0,VLOOKUP(E38,'Prix Matiere'!$A$4:$J$65,10)) -> 16.895876 | M38: =L38*K38 -> 28.321713 | N38: =IF(C38=0,0,(6.0924*J38)+10) -> 18.169908 | O38: =N38*MinuteMO -> 15.444422 | P38: =IF(J38=0,0,J38*VLOOKUP(E38,'Prix Matiere'!$A$4:$L$60,12)) -> 8.8506 | Q38: =IF(J38=0,0,P38*VLOOKUP(E38,'Prix Matiere'!$A$4:$L$60,11)) -> 6.8415138
B39: =E39 -> Peuplier 15 mm | C39: =IF(C38=0,0,E25-2*D38) -> 210.2 | D39: =D38 -> 25 | E39: ="Peuplier 15 mm" -> Peuplier 15 mm | F39: =IF(C39=0,0,2) -> 2 | J39: =IF(C39=0,0,(C39/100)*(D39/100)*F39) -> 1.051 | K39: =J39/0.8 -> 1.31375 | L39: =IF(E39=0,0,VLOOKUP(E39,'Prix Matiere'!$A$4:$J$65,10)) -> 16.895876 | M39: =L39*K39 -> 22.196957 | N39: =IF(C39=0,0,(6.0924*J39)+10) -> 16.403112 | O39: =N39*MinuteMO -> 13.942646 | P39: =IF(J39=0,0,J39*VLOOKUP(E39,'Prix Matiere'!$A$4:$L$60,12)) -> 6.9366 | Q39: =IF(J39=0,0,P39*VLOOKUP(E39,'Prix Matiere'!$A$4:$L$60,11)) -> 5.3619918
B40: Angles cp 15 | C40: =IF(C36=0,0,45) -> 45 | D40: =IF(C40=0,0,45) -> 45 | E40: Peuplier 15 mm | F40: =IF(C40=0,0,4) -> 4 | J40: =IF(C40=0,0,(C40/100)*(D40/100)*F40) -> 0.81 | K40: =J40/0.8 -> 1.0125 | L40: =IF(E40=0,0,VLOOKUP(E40,'Prix Matiere'!$A$4:$J$65,10)) -> 16.895876 | M40: =L40*K40 -> 17.107075 | N40: =IF(C40=0,0,(6.0924*J40)+10) -> 14.934844 | O40: =N40*MinuteMO -> 12.694617 | P40: =IF(J40=0,0,J40*VLOOKUP(E40,'Prix Matiere'!$A$4:$L$60,12)) -> 5.346 | Q40: =IF(J40=0,0,P40*VLOOKUP(E40,'Prix Matiere'!$A$4:$L$60,11)) -> 4.132458
B41: =G19 -> Mrt Ouvert | C41: =IF(B41=0,0,IF(B41="Mrt Ouvert",0,C25)) -> 0 | D41: =IF(B41=0,0,IF(B41="Mrt Ouvert",0,E25)) -> 0 | E41: =VLOOKUP(G19,$A$77:$C$81,2) -> 0 | F41: =IF(C41=0,0,1) -> 0 | J41: =IF(C41=0,0,(C41/100)*(D41/100)*F41) -> 0 | K41: =J41/0.8 -> 0 | L41: =IF(E41=0,0,IF(E41="Carton",Carton,VLOOKUP(E41,'Prix Matiere'!$A$4:$J$65,10))) -> 0 | M41: =L41*K41 -> 0 | N41: =IF(C41=0,0,1+(11*J41)) -> 0 | O41: =N41*MinuteMO -> 0 | P41: =IF(J41=0,0,IF(E41="Carton",Poids_Carton*J41,J41*VLOOKUP(E41,'Prix Matiere'!$A$4:$L$60,12))) -> 0 | Q41: =IF(J41=0,0,P41*VLOOKUP(E41,'Prix Matiere'!$A$4:$L$60,11)) -> 0
B42: =F19 -> Mrt Ouvert | C42: =IF(B42=0,0,IF(B42="Mrt Ouvert",0,C25)) -> 0 | D42: =IF(B42=0,0,IF(B42="Mrt Ouvert",0,E25)) -> 0 | E42: =VLOOKUP($F$19,$A$77:$C$81,2) -> 0 | F42: =IF(C42=0,0,1) -> 0 | J42: =IF(C42=0,0,(C42/100)*(D42/100)*F42) -> 0 | K42: =J42/0.8 -> 0 | L42: =IF(E42=0,0,IF(E42="Carton",Carton,VLOOKUP(E42,'Prix Matiere'!$A$4:$J$65,10))) -> 0 | M42: =L42*K42 -> 0 | N42: =IF(C42=0,0,1+(11*J42)) -> 0 | O42: =N42*MinuteMO -> 0 | P42: =IF(J42=0,0,IF(E42="Carton",Poids_Carton*J42,J42*VLOOKUP(E42,'Prix Matiere'!$A$4:$L$60,12))) -> 0 | Q42: =IF(J42=0,0,P42*VLOOKUP(E42,'Prix Matiere'!$A$4:$L$60,11)) -> 0
O45: =N45*MinuteMO -> 0
L47: =IF(E47=0,0,VLOOKUP(E47,'Prix Matiere'!$A$4:$J$65,10)) -> 0 | M47: =SUM(M34:M46) -> 90.993176 | N47: =SUM(N34:N46) -> 68.348321 | O47: =N47*MinuteMO -> 58.096073 | P47: =SUM(P36:P46) -> 30.98816 | Q47: =SUM(Q36:Q46) -> 21.105764
B48: Total matière | C48: =IF($F$4=0,0,SUM(M36:M42)) -> 90.993176 | E48: Contreplaqué | F48: =CONCATENATE(ROUNDUP(SUM(J38:J40),2)," m²") -> 3,21 m² | G48: =(SUM(M38:M40)) -> 67.625745
B49: Total MO | C49: =IF($F$4=0,0,SUM(O36:O42)) -> 58.096073 | D49: =IF($F$4=0,0,SUM(N36:N42)) -> 68.348321 | E49: Bois massif | F49: =CONCATENATE(ROUNDUP(SUM(J36:J37),2)," m²") -> 0,99 m² | G49: =(SUM(M36:M37)) -> 23.367431
B50: Total frais généraux | C50: =IF($F$4=0,0,((C48+C49)/Frais_Généraux)-(C48+C49)) -> 80.278826
B51: Total revient | C51: =IF($F$4=0,0,SUM(C48:C50)) -> 229.36807
B52: Marge | C52: =IF($F$4=0,0,(C51/(1-Marge)-C51)) -> 17.264264 | D52: =C51+C52 -> 246.63234
B53: Remise (-) ou Majoration (+) en % | C53: =IF($F$5="BOVIS",((C51+C52)*(1+C54))-(C51+C52),((C51+C52)*(1+D53))-(C51+C52)) -> 0
C54: =IF($F$5="BOVIS",0.03,0) -> 0
B55: Prix de vente | C55: =SUM(C51:C54) -> 246.63234 | E55: Divers | G55: =C48-SUM(G48:G52) -> 0
A58: Peuplier 15 mm | B58: Peuplier 15 mm | C58: Peuplier 15 mm | D58: 1.5
A60: Pin raboté 4 faces | B60: Pin 21 mm | C60: Pin 21 mm | D60: 2.1
A63: Bois | B63: 4.2
A64: Métal x 2 sur bouts | B64: 2
A65: Métal x 4 sur GC | B65: 0
...

Sheet T1 LOUVRE
A1: Caisse Tableau Louvre
E3: =IF(C19="Boulons et platines","Boulons et Platines",0) -> 0 | F3: =IF(E3="Boulons et Platines","Nbre de Trous",0) -> 0 | G3: =IF(E3="Boulons et Platines","Dim du Bord",0) -> 0
E4: =IF(C19="Vis bois",0,"Trous dans la Longueur") -> 0 | F4: =IF(E4=0,0,IF(C54<100,2,IF(C54<150,3,IF(C54<200,4,IF(C54<250,5,IF(C54<300,6,7)))))) -> 0 | G4: =IF(F4=0,0,IF(F4=3,0,(($C$54-32)/(F4-1))+16)) -> 0
E5: =IF(F4=6,"2ème Trou",IF(F4=7,"2ème Trou",0)) -> 0 | G5: =IF(E5=0,0,G4+G4-16) -> 0
E6: =IF(C19="Vis bois",0,"Trous dans la Hauteur") -> 0 | F6: =IF(E6=0,0,IF(D54<100,2,IF(D54<150,3,IF(D54<200,4,IF(D54<250,5,IF(D54<310,6,7)))))) -> 0 | G6: =IF(F6=0,0,IF(F6=3,0,(($D$54-32)/(F6-1))+16)) -> 0
E7: =IF(F6=6,"2ème Trou",IF(F6=7,"2ème Trou",0)) -> 0 | G7: =IF(E7=0,0,G6+G6-16) -> 0
B9: N° de dossier | E9: Responsable Dossier | F9: Grégory MORA
B10: Ville de destination | E10: Client | F10: ESI
B11: N° de caisse | E11: Délai
B13: Type de Contreplaqué | C13: Peuplier 15 mm | I13: =VLOOKUP($F$10,'Infos Clients'!$B$2:$G$10,2) -> #VALUE!
B15: Barres | C15: Pin raboté 4 faces | E15: Garnissage | F15: Valsem
B17: Type d'isolant | C17: Isotherme en 50
B19: Fermeture | C19: Vis bois | E19: Peinture | F19: Non
E20: =IF(F19="Oui","Type de Peinture",0) -> 0 | F20: =IF(F19="Non",0,VLOOKUP(F10,'Infos Clients'!B2:E10,4)) -> 0
B21: Poignées | C21: Bois | E21: Tyvek | F21: Non
B23: Skis | C23: Skis en 30 mm | E23: Option Calage | F23: Aucun
B25: =IF(F23="Aucun"," ",F23) | D25: =IF(F21="Oui","+",0) -> 0 | E25: =IF(F21="Oui","Mousse Garnie Tyvek",0) -> 0
B26: =IF(F10="Bovis","Attention retirer 2 mm aux dimensions transmises",0) -> 0
C28: Longueur | D28: Epaisseur | E28: Hauteur
B29: =IF(B31="Aucun","Dimensions intérieures utiles","Dimensions de l'œuvre") -> Dimensions de l'œuvre | C29: 21.7 | D29: 16.5 | E29: 3.5
A31: Type de calage | B31: Bandes de mousse
C32: Largeur | D32: Longueur | E32: Epaisseur | F32: Quantité
B33: Dessus | C33: 10
B34: Dessous | C34: 10
B35: Agglocelle 50 mm | C35: =+IF(C29=0,0,IF(C29>70,12,6)) -> 6 | F35: =IF(C29>300,6,IF(C29>250,5,IF(C29>200,4,IF(C29>150,3,IF(C29>120,3,2))))) -> 2
B36: Rattrapage
B38: Remplissage 1
B39: Remplissage 2
B41: Dimensions intérieures caisse | C41: =C29+VLOOKUP(C17,A132:P138,2)+VLOOKUP(B31,A161:L166,2) -> 41.9 | D41: =D29+VLOOKUP($B$31,A161:L166,3)+VLOOKUP($C$17,A132:P138,3) -> 41.5 | E41: =E29+VLOOKUP($B$31,A161:L166,4)+VLOOKUP($C$17,A132:P138,4) -> 23.7 | F41: Prix d'achat Arckx
B43: Dimensions extérieures caisse | C43: =C41+VLOOKUP(C21,A146:B148,2)+VLOOKUP(C13,A125:D125,4)*2+VLOOKUP(C15,A127:D127,4)*2 -> 53.3 | D43: =IF(OR($F$23="Aucun",$F$23="Stabilisateur"),$D$41+VLOOKUP($C$13,$A$125:$D$125,4)*2+VLOOKUP($C$15,$A$127:$D$127,4)*2+0.5,$E$41+VLOOKUP($C$13,$A$125:$D$125,5)*2+VLOOKUP($C$15,$A$127:$D$127,4)*2) -> 49.2 | E43: =IF(OR($F$23="Aucun",$F$23="Stabilisateur"),$E$41+VLOOKUP($C$13,$A$125:$D$125,4)*2+VLOOKUP($C$15,$A$127:$D$127,4)*2+VLOOKUP($C$23,$A$168:$B$170,2),$D$41+VLOOKUP($C$13,$A$125:$D$125,4)*2+VLOOKUP($C$15,$A$127:$D$127,4)*2+VLOOKUP($C$23,$A$168:$B$170,2)+VLOOKUP($F$23,$A$150:$D$153,4)+0.5) -> 33.9 | F43: =ROUNDUP(C122,0) -> 222
B45: Poids de la Caisse | C45: =Q114 -> 13.167892 | D45: Kg | E45: Bilan Carbone
B46: Minutes de Production | C46: =D116 -> 104.25419 | D46: Min | E46: =R114 -> 10.759756
B48: Commentaires
F53: Quantité | Q53: Poids KG | R53: CO²
A54: Grand côtés | B54: =VLOOKUP(C13,A125:D125,2) -> Peuplier 15 mm | C54: =IF(C41=0,0,C41+2*(VLOOKUP(B54,A125:D125,4)+VLOOKUP(C15,A127:D127,4))) -> 49.1 | D54: =IF(E41=0,0,E41+2*(VLOOKUP(B54,A125:D125,4)+VLOOKUP(C15,A127:D127,4))) -> 30.9 | E54: =B54 -> Peuplier 15 mm | F54: 2 | J54: =IF(C54=0,0,(C54/100)*(D54/100)*F54) -> 0.303438 | K54: =J54/0.8 -> 0.3792975 | L54: =IF(E54=0,0,VLOOKUP(E54,'Prix Matiere'!$A$4:$J$65,10)) -> 16.895876 | M54: =L54*K54 -> 6.4085636 | N54: =IF(J54=0,0,(7.0924*J54)+15) -> 17.152104 | O54: =N54*MinuteMO -> 14.579288 | Q54: =IF(J54=0,0,J54*VLOOKUP(E54,'Prix Matiere'!$A$4:$L$60,12)) -> 2.0026908 | R54: =IF(J54=0,0,Q54*VLOOKUP(E54,'Prix Matiere'!$A$4:$L$60,11)) -> 1.54808
A55: Dessus dessous | B55: =VLOOKUP(C13,A125:D125,3) -> Peuplier 15 mm | C55: =C54 -> 49.1 | D55: =D41 -> 41.5 | E55: =B55 -> Peuplier 15 mm | F55: 2 | J55: =IF(C55=0,0,(C55/100)*(D55/100)*F55) -> 0.40753 | K55: =J55/0.8 -> 0.5094125 | L55: =IF(E55=0,0,VLOOKUP(E55,'Prix Matiere'!$A$4:$J$65,10)) -> 16.895876 | M55: =L55*K55 -> 8.6069706 | N55: =IF(J55=0,0,(7.0924*J55)+15) -> 17.890366 | O55: =N55*MinuteMO -> 15.206811 | Q55: =IF(J55=0,0,J55*VLOOKUP(E55,'Prix Matiere'!$A$4:$L$60,12)) -> 2.689698 | R55: =IF(J55=0,0,Q55*VLOOKUP(E55,'Prix Matiere'!$A$4:$L$60,11)) -> 2.0791366
A56: Bouts | B56: =VLOOKUP(C13,A125:D125,3) -> Peuplier 15 mm | C56: =E41 -> 23.7 | D56: =D41 -> 41.5 | E56: =B56 -> Peuplier 15 mm | F56: 2 | J56: =IF(C56=0,0,(C56/100)*(D56/100)*F56) -> 0.19671 | K56: =J56/0.8 -> 0.2458875 | L56: =IF(E56=0,0,VLOOKUP(E56,'Prix Matiere'!$A$4:$J$65,10)) -> 16.895876 | M56: =L56*K56 -> 4.1544848 | N56: =IF(J56=0,0,(7.0924*J56)+15) -> 16.395146 | O56: =N56*MinuteMO -> 13.935874 | Q56: =IF(J56=0,0,J56*VLOOKUP(E56,'Prix Matiere'!$A$4:$L$60,12)) -> 1.298286 | R56: =IF(J56=0,0,Q56*VLOOKUP(E56,'Prix Matiere'!$A$4:$L$60,11)) -> 1.0035751
J57: =IF(C57=0,0,(C57/100)*(D57/100)*F57) -> 0 | K57: =J57/0.8 -> 0 | Q57: =IF(J57=0,0,J57*VLOOKUP(E57,'Prix Matiere'!$A$4:$L$60,12)) -> 0
J58: =IF(C58=0,0,(C58/100)*(D58/100)*F58) -> 0 | K58: =J58/0.8 -> 0 | Q58: =IF(J58=0,0,J58*VLOOKUP(E58,'Prix Matiere'!$A$4:$L$60,12)) -> 0
A59: Barres | B59: Barres de GC | C59: =C54 -> 49.1 | D59: =IF(D54>80,9.4,7) -> 7 | E59: =IF($C$15="Pin raboté 4 faces","Barres 21 R4F","Barres 19 mm") -> Barres 21 R4F | F59: 4 | J59: =IF(C59=0,0,(C59/100)*(D59/100)*F59) -> 0.13748 | K59: =J59/0.8 -> 0.17185 | L59: =IF(E59=0,0,VLOOKUP(E59,'Prix Matiere'!$A$4:$J$65,10)) -> 18.969072 | M59: =L59*K59 -> 3.2598351 | N59: =IF(J59=0,0,1+(11*J59)) -> 2.51228 | O59: =N59*MinuteMO -> 2.135438 | Q59: =IF(J59=0,0,J59*VLOOKUP(E59,'Prix Matiere'!$A$4:$L$60,12)) -> 1.3748 | R59: =IF(J59=0,0,Q59*VLOOKUP(E59,'Prix Matiere'!$A$4:$L$60,11)) -> 0.6654032
...

Sheet T1-T6 LOUVRE
A1: Caisse Tableau Louvre de 2 à 6 Oeuvres
E3: =IF(C19="Boulons et platines","Boulons et Platines",0) -> 0 | F3: =IF(E3="Boulons et Platines","Nbre de Trous",0) -> 0 | G3: =IF(E3="Boulons et Platines","Dim du Bord",0) -> 0
E4: =IF(C19="Vis bois",0,"Trous dans la Longueur") -> 0 | F4: =IF(E4=0,0,IF(C91<100,2,IF(C91<150,3,IF(C91<200,4,IF(C91<250,5,IF(C91<300,6,7)))))) -> 0 | G4: =IF(F4=0,0,IF(F4=3,0,(($C$91-32)/(F4-1))+16)) -> 0
E5: =IF(F4=6,"2ème Trou",IF(F4=7,"2ème Trou",0)) -> 0 | G5: =IF(E5=0,0,G4+G4-16) -> 0
E6: =IF(C19="Vis bois",0,"Trous dans la Hauteur") -> 0 | F6: =IF(E6=0,0,IF(D91<100,2,IF(D91<150,3,IF(D91<200,4,IF(D91<250,5,IF(D91<310,6,7)))))) -> 0 | G6: =IF(F6=0,0,IF(F6=3,0,(($D$91-32)/(F6-1))+16)) -> 0
E7: =IF(F6=6,"2ème Trou",IF(F6=7,"2ème Trou",0)) -> 0 | G7: =IF(E7=0,0,G6+G6-16) -> 0
B9: N° de dossier | E9: Responsable Dossier
B10: Ville de destination | E10: Client | F10: ESI
B11: N° de caisse | E11: Délai
B13: Type de Contreplaqué | C13: Peuplier 15 mm
B15: Barres | C15: Pin raboté 4 faces | E15: Garnissage | F15: Valsem | I15: =VLOOKUP($F$10,'Infos Clients'!$B$2:$G$10,2) -> #VALUE!
B17: Type d'isolant | C17: Aucun
B19: Fermeture | C19: Vis bois | E19: Peinture | F19: Non
E20: =IF(F19="Oui","Type de Peinture",0) -> 0 | F20: =IF(F19="Non",0,VLOOKUP(F10,'Infos Clients'!B2:E10,4)) -> 0
B21: Poignées | C21: Bois | E21: Tyvek | F21: Non
B23: Skis | C23: Skis en 30 mm | E23: Option Calage | F23: Aucun
B25: =IF(F23="Aucun"," ",F23) | D25: =IF(F21="Oui","+",0) -> 0 | E25: =IF(F21="Oui","Mousse Garnie Tyvek",0) -> 0
